{"type": "end", "timestamp": "2024-09-27T06:17:06.860727", "task_id": "demo.main", "step_id": "demo.main.guessing_game", "result": null, "exception": {"type": "asyncio.exceptions.CancelledError", "args": [], "details": "Traceback (most recent call last):\n  File \"/Users/collinwebb/miniconda3/lib/python3.12/asyncio/runners.py\", line 118, in run\n    return self._loop.run_until_complete(task)\n           ^^^^^^^^^^^^^^^^^^^^^^^^^^^^^^^^^^^\n  File \"/Users/collinwebb/miniconda3/lib/python3.12/asyncio/base_events.py\", line 687, in run_until_complete\n    return future.result()\n           ^^^^^^^^^^^^^^^\n  File \"/Users/collinwebb/repos/quest_framework/demos/guessing_game.py\", line 48, in main\n    await manager.wait_for_completion('demo', None)\n  File \"/Users/collinwebb/repos/quest_framework/src/quest/manager.py\", line 102, in wait_for_completion\n    return await self._get_workflow(workflow_id).wait_for_completion(identity)\n           ^^^^^^^^^^^^^^^^^^^^^^^^^^^^^^^^^^^^^^^^^^^^^^^^^^^^^^^^^^^^^^^^^^^\n  File \"/Users/collinwebb/repos/quest_framework/src/quest/historian.py\", line 1005, in wait_for_completion\n    async for _ in self.stream_resources(identity):\n  File \"/Users/collinwebb/repos/quest_framework/src/quest/historian.py\", line 987, in stream_resources\n    await self._resource_queues[identity].get()\n  File \"/Users/collinwebb/miniconda3/lib/python3.12/asyncio/queues.py\", line 158, in get\n    await getter\nasyncio.exceptions.CancelledError\n\nDuring handling of the above exception, another exception occurred:\n\nTraceback (most recent call last):\n  File \"/Users/collinwebb/miniconda3/lib/python3.12/asyncio/runners.py\", line 194, in run\n    return runner.run(main)\n           ^^^^^^^^^^^^^^^^\n  File \"/Users/collinwebb/miniconda3/lib/python3.12/asyncio/runners.py\", line 123, in run\n    raise KeyboardInterrupt()\nKeyboardInterrupt\n\nDuring handling of the above exception, another exception occurred:\n\nTraceback (most recent call last):\n  File \"/Users/collinwebb/repos/quest_framework/src/quest/historian.py\", line 552, in handle_step\n    result = await result\n             ^^^^^^^^^^^^\n  File \"/Users/collinwebb/repos/quest_framework/demos/guessing_game.py\", line 27, in guessing_game\n    guess = int(await get_input('Guess: '))\n                ^^^^^^^^^^^^^^^^^^^^^^^^^^\n  File \"/Users/collinwebb/repos/quest_framework/src/quest/wrappers.py\", line 18, in new_func\n    return await find_historian().handle_step(func.__name__, func, *args, **kwargs)\n           ^^^^^^^^^^^^^^^^^^^^^^^^^^^^^^^^^^^^^^^^^^^^^^^^^^^^^^^^^^^^^^^^^^^^^^^^\n  File \"/Users/collinwebb/repos/quest_framework/src/quest/historian.py\", line 552, in handle_step\n    result = await result\n             ^^^^^^^^^^^^\n  File \"/Users/collinwebb/repos/quest_framework/demos/guessing_game.py\", line 20, in get_input\n    return await ainput(*args)\n           ^^^^^^^^^^^^^^^^^^^\n  File \"/Users/collinwebb/repos/quest_framework/src/quest/utils.py\", line 5, in ainput\n    return await asyncio.to_thread(input, *args)\n           ^^^^^^^^^^^^^^^^^^^^^^^^^^^^^^^^^^^^^\n  File \"/Users/collinwebb/miniconda3/lib/python3.12/asyncio/threads.py\", line 25, in to_thread\n    return await loop.run_in_executor(None, func_call)\n           ^^^^^^^^^^^^^^^^^^^^^^^^^^^^^^^^^^^^^^^^^^^\nasyncio.exceptions.CancelledError\n"}}